Workbook

Sheet ShotPlanner
A1: Selected | B1: Group Name | D1: Shot 1 | E1: Shot 3 | F1: Shot 4 | G1: Shot 5 | H1: Shot 6 | I1: Shot 7 | J1: Shot 8 | K1: Shot 9 | L1: Shot 10 | M1: Shot 11 | N1: Shot 12 | O1: Shot 13 | P1: Shot 14 | Q1: Shot 15
A3: FALSE | B3: =IFERROR(__xludf.DUMMYFUNCTION("UNIQUE(FILTER(VideoTimeStamps!A2:A1000, VideoTimeStamps!A2:A1000<>""""))"),"Jorynn") -> Jorynn | D3: {=IF(OR($B3="", D$2=""), "", IFERROR(INDEX(VideoTimeStamps!$C:$C, MATCH(1, INDEX((VideoTimeStamps!$A:$A=$B3)*ISNUMBER(SEARCH(D$2, VideoTimeStamps!$E:$E)), 0), 0)), ""))} | E3: {=IF(OR($B3="", E$2=""), "", IFERROR(INDEX(VideoTimeStamps!$C:$C, MATCH(1, INDEX((VideoTimeStamps!$A:$A=$B3)*ISNUMBER(SEARCH(E$2, VideoTimeStamps!$E:$E)), 0), 0)), ""))} | F3: {=IF(OR($B3="", F$2=""), "", IFERROR(INDEX(VideoTimeStamps!$C:$C, MATCH(1, INDEX((VideoTimeStamps!$A:$A=$B3)*ISNUMBER(SEARCH(F$2, VideoTimeStamps!$E:$E)), 0), 0)), ""))} | G3: {=IF(OR($B3="", G$2=""), "", IFERROR(INDEX(VideoTimeStamps!$C:$C, MATCH(1, INDEX((VideoTimeStamps!$A:$A=$B3)*ISNUMBER(SEARCH(G$2, VideoTimeStamps!$E:$E)), 0), 0)), ""))} | H3: {=IF(OR($B3="", H$2=""), "", IFERROR(INDEX(VideoTimeStamps!$C:$C, MATCH(1, INDEX((VideoTimeStamps!$A:$A=$B3)*ISNUMBER(SEARCH(H$2, VideoTimeStamps!$E:$E)), 0), 0)), ""))} | I3: {=IF(OR($B3="", I$2=""), "", IFERROR(INDEX(VideoTimeStamps!$C:$C, MATCH(1, INDEX((VideoTimeStamps!$A:$A=$B3)*ISNUMBER(SEARCH(I$2, VideoTimeStamps!$E:$E)), 0), 0)), ""))} | J3: {=IF(OR($B3="", J$2=""), "", IFERROR(INDEX(VideoTimeStamps!$C:$C, MATCH(1, INDEX((VideoTimeStamps!$A:$A=$B3)*ISNUMBER(SEARCH(J$2, VideoTimeStamps!$E:$E)), 0), 0)), ""))} | K3: {=IF(OR($B3="", K$2=""), "", IFERROR(INDEX(VideoTimeStamps!$C:$C, MATCH(1, INDEX((VideoTimeStamps!$A:$A=$B3)*ISNUMBER(SEARCH(K$2, VideoTimeStamps!$E:$E)), 0), 0)), ""))} | ... Q3: {=IF(OR($B3="", Q$2=""), "", IFERROR(INDEX(VideoTimeStamps!$C:$C, MATCH(1, INDEX((VideoTimeStamps!$A:$A=$B3)*ISNUMBER(SEARCH(Q$2, VideoTimeStamps!$E:$E)), 0), 0)), ""))}
A4: FALSE | B4: =IFERROR(__xludf.DUMMYFUNCTION("""COMPUTED_VALUE"""),"Jasmine") -> Jasmine | D4: {=IF(OR($B4="", D$2=""), "", IFERROR(INDEX(VideoTimeStamps!$C:$C, MATCH(1, INDEX((VideoTimeStamps!$A:$A=$B4)*ISNUMBER(SEARCH(D$2, VideoTimeStamps!$E:$E)), 0), 0)), ""))} | E4: {=IF(OR($B4="", E$2=""), "", IFERROR(INDEX(VideoTimeStamps!$C:$C, MATCH(1, INDEX((VideoTimeStamps!$A:$A=$B4)*ISNUMBER(SEARCH(E$2, VideoTimeStamps!$E:$E)), 0), 0)), ""))} | F4: {=IF(OR($B4="", F$2=""), "", IFERROR(INDEX(VideoTimeStamps!$C:$C, MATCH(1, INDEX((VideoTimeStamps!$A:$A=$B4)*ISNUMBER(SEARCH(F$2, VideoTimeStamps!$E:$E)), 0), 0)), ""))} | G4: {=IF(OR($B4="", G$2=""), "", IFERROR(INDEX(VideoTimeStamps!$C:$C, MATCH(1, INDEX((VideoTimeStamps!$A:$A=$B4)*ISNUMBER(SEARCH(G$2, VideoTimeStamps!$E:$E)), 0), 0)), ""))} | H4: {=IF(OR($B4="", H$2=""), "", IFERROR(INDEX(VideoTimeStamps!$C:$C, MATCH(1, INDEX((VideoTimeStamps!$A:$A=$B4)*ISNUMBER(SEARCH(H$2, VideoTimeStamps!$E:$E)), 0), 0)), ""))} | I4: {=IF(OR($B4="", I$2=""), "", IFERROR(INDEX(VideoTimeStamps!$C:$C, MATCH(1, INDEX((VideoTimeStamps!$A:$A=$B4)*ISNUMBER(SEARCH(I$2, VideoTimeStamps!$E:$E)), 0), 0)), ""))} | J4: {=IF(OR($B4="", J$2=""), "", IFERROR(INDEX(VideoTimeStamps!$C:$C, MATCH(1, INDEX((VideoTimeStamps!$A:$A=$B4)*ISNUMBER(SEARCH(J$2, VideoTimeStamps!$E:$E)), 0), 0)), ""))} | K4: {=IF(OR($B4="", K$2=""), "", IFERROR(INDEX(VideoTimeStamps!$C:$C, MATCH(1, INDEX((VideoTimeStamps!$A:$A=$B4)*ISNUMBER(SEARCH(K$2, VideoTimeStamps!$E:$E)), 0), 0)), ""))} | ... Q4: {=IF(OR($B4="", Q$2=""), "", IFERROR(INDEX(VideoTimeStamps!$C:$C, MATCH(1, INDEX((VideoTimeStamps!$A:$A=$B4)*ISNUMBER(SEARCH(Q$2, VideoTimeStamps!$E:$E)), 0), 0)), ""))}
A5: FALSE | B5: =IFERROR(__xludf.DUMMYFUNCTION("""COMPUTED_VALUE"""),"Nessa") -> Nessa | D5: {=IF(OR($B5="", D$2=""), "", IFERROR(INDEX(VideoTimeStamps!$C:$C, MATCH(1, INDEX((VideoTimeStamps!$A:$A=$B5)*ISNUMBER(SEARCH(D$2, VideoTimeStamps!$E:$E)), 0), 0)), ""))} | E5: {=IF(OR($B5="", E$2=""), "", IFERROR(INDEX(VideoTimeStamps!$C:$C, MATCH(1, INDEX((VideoTimeStamps!$A:$A=$B5)*ISNUMBER(SEARCH(E$2, VideoTimeStamps!$E:$E)), 0), 0)), ""))} | F5: {=IF(OR($B5="", F$2=""), "", IFERROR(INDEX(VideoTimeStamps!$C:$C, MATCH(1, INDEX((VideoTimeStamps!$A:$A=$B5)*ISNUMBER(SEARCH(F$2, VideoTimeStamps!$E:$E)), 0), 0)), ""))} | G5: {=IF(OR($B5="", G$2=""), "", IFERROR(INDEX(VideoTimeStamps!$C:$C, MATCH(1, INDEX((VideoTimeStamps!$A:$A=$B5)*ISNUMBER(SEARCH(G$2, VideoTimeStamps!$E:$E)), 0), 0)), ""))} | H5: {=IF(OR($B5="", H$2=""), "", IFERROR(INDEX(VideoTimeStamps!$C:$C, MATCH(1, INDEX((VideoTimeStamps!$A:$A=$B5)*ISNUMBER(SEARCH(H$2, VideoTimeStamps!$E:$E)), 0), 0)), ""))} | I5: {=IF(OR($B5="", I$2=""), "", IFERROR(INDEX(VideoTimeStamps!$C:$C, MATCH(1, INDEX((VideoTimeStamps!$A:$A=$B5)*ISNUMBER(SEARCH(I$2, VideoTimeStamps!$E:$E)), 0), 0)), ""))} | J5: {=IF(OR($B5="", J$2=""), "", IFERROR(INDEX(VideoTimeStamps!$C:$C, MATCH(1, INDEX((VideoTimeStamps!$A:$A=$B5)*ISNUMBER(SEARCH(J$2, VideoTimeStamps!$E:$E)), 0), 0)), ""))} | K5: {=IF(OR($B5="", K$2=""), "", IFERROR(INDEX(VideoTimeStamps!$C:$C, MATCH(1, INDEX((VideoTimeStamps!$A:$A=$B5)*ISNUMBER(SEARCH(K$2, VideoTimeStamps!$E:$E)), 0), 0)), ""))} | ... Q5: {=IF(OR($B5="", Q$2=""), "", IFERROR(INDEX(VideoTimeStamps!$C:$C, MATCH(1, INDEX((VideoTimeStamps!$A:$A=$B5)*ISNUMBER(SEARCH(Q$2, VideoTimeStamps!$E:$E)), 0), 0)), ""))}
A6: FALSE | B6: =IFERROR(__xludf.DUMMYFUNCTION("""COMPUTED_VALUE"""),"jingwen") -> jingwen | D6: {=IF(OR($B6="", D$2=""), "", IFERROR(INDEX(VideoTimeStamps!$C:$C, MATCH(1, INDEX((VideoTimeStamps!$A:$A=$B6)*ISNUMBER(SEARCH(D$2, VideoTimeStamps!$E:$E)), 0), 0)), ""))} | E6: {=IF(OR($B6="", E$2=""), "", IFERROR(INDEX(VideoTimeStamps!$C:$C, MATCH(1, INDEX((VideoTimeStamps!$A:$A=$B6)*ISNUMBER(SEARCH(E$2, VideoTimeStamps!$E:$E)), 0), 0)), ""))} | F6: {=IF(OR($B6="", F$2=""), "", IFERROR(INDEX(VideoTimeStamps!$C:$C, MATCH(1, INDEX((VideoTimeStamps!$A:$A=$B6)*ISNUMBER(SEARCH(F$2, VideoTimeStamps!$E:$E)), 0), 0)), ""))} | G6: {=IF(OR($B6="", G$2=""), "", IFERROR(INDEX(VideoTimeStamps!$C:$C, MATCH(1, INDEX((VideoTimeStamps!$A:$A=$B6)*ISNUMBER(SEARCH(G$2, VideoTimeStamps!$E:$E)), 0), 0)), ""))} | H6: {=IF(OR($B6="", H$2=""), "", IFERROR(INDEX(VideoTimeStamps!$C:$C, MATCH(1, INDEX((VideoTimeStamps!$A:$A=$B6)*ISNUMBER(SEARCH(H$2, VideoTimeStamps!$E:$E)), 0), 0)), ""))} | I6: {=IF(OR($B6="", I$2=""), "", IFERROR(INDEX(VideoTimeStamps!$C:$C, MATCH(1, INDEX((VideoTimeStamps!$A:$A=$B6)*ISNUMBER(SEARCH(I$2, VideoTimeStamps!$E:$E)), 0), 0)), ""))} | J6: {=IF(OR($B6="", J$2=""), "", IFERROR(INDEX(VideoTimeStamps!$C:$C, MATCH(1, INDEX((VideoTimeStamps!$A:$A=$B6)*ISNUMBER(SEARCH(J$2, VideoTimeStamps!$E:$E)), 0), 0)), ""))} | K6: {=IF(OR($B6="", K$2=""), "", IFERROR(INDEX(VideoTimeStamps!$C:$C, MATCH(1, INDEX((VideoTimeStamps!$A:$A=$B6)*ISNUMBER(SEARCH(K$2, VideoTimeStamps!$E:$E)), 0), 0)), ""))} | ... Q6: {=IF(OR($B6="", Q$2=""), "", IFERROR(INDEX(VideoTimeStamps!$C:$C, MATCH(1, INDEX((VideoTimeStamps!$A:$A=$B6)*ISNUMBER(SEARCH(Q$2, VideoTimeStamps!$E:$E)), 0), 0)), ""))}
A7: FALSE | B7: =IFERROR(__xludf.DUMMYFUNCTION("""COMPUTED_VALUE"""),"qian") -> qian | D7: {=IF(OR($B7="", D$2=""), "", IFERROR(INDEX(VideoTimeStamps!$C:$C, MATCH(1, INDEX((VideoTimeStamps!$A:$A=$B7)*ISNUMBER(SEARCH(D$2, VideoTimeStamps!$E:$E)), 0), 0)), ""))} | E7: {=IF(OR($B7="", E$2=""), "", IFERROR(INDEX(VideoTimeStamps!$C:$C, MATCH(1, INDEX((VideoTimeStamps!$A:$A=$B7)*ISNUMBER(SEARCH(E$2, VideoTimeStamps!$E:$E)), 0), 0)), ""))} | F7: {=IF(OR($B7="", F$2=""), "", IFERROR(INDEX(VideoTimeStamps!$C:$C, MATCH(1, INDEX((VideoTimeStamps!$A:$A=$B7)*ISNUMBER(SEARCH(F$2, VideoTimeStamps!$E:$E)), 0), 0)), ""))} | G7: {=IF(OR($B7="", G$2=""), "", IFERROR(INDEX(VideoTimeStamps!$C:$C, MATCH(1, INDEX((VideoTimeStamps!$A:$A=$B7)*ISNUMBER(SEARCH(G$2, VideoTimeStamps!$E:$E)), 0), 0)), ""))} | H7: {=IF(OR($B7="", H$2=""), "", IFERROR(INDEX(VideoTimeStamps!$C:$C, MATCH(1, INDEX((VideoTimeStamps!$A:$A=$B7)*ISNUMBER(SEARCH(H$2, VideoTimeStamps!$E:$E)), 0), 0)), ""))} | I7: {=IF(OR($B7="", I$2=""), "", IFERROR(INDEX(VideoTimeStamps!$C:$C, MATCH(1, INDEX((VideoTimeStamps!$A:$A=$B7)*ISNUMBER(SEARCH(I$2, VideoTimeStamps!$E:$E)), 0), 0)), ""))} | J7: {=IF(OR($B7="", J$2=""), "", IFERROR(INDEX(VideoTimeStamps!$C:$C, MATCH(1, INDEX((VideoTimeStamps!$A:$A=$B7)*ISNUMBER(SEARCH(J$2, VideoTimeStamps!$E:$E)), 0), 0)), ""))} | K7: {=IF(OR($B7="", K$2=""), "", IFERROR(INDEX(VideoTimeStamps!$C:$C, MATCH(1, INDEX((VideoTimeStamps!$A:$A=$B7)*ISNUMBER(SEARCH(K$2, VideoTimeStamps!$E:$E)), 0), 0)), ""))} | ... Q7: {=IF(OR($B7="", Q$2=""), "", IFERROR(INDEX(VideoTimeStamps!$C:$C, MATCH(1, INDEX((VideoTimeStamps!$A:$A=$B7)*ISNUMBER(SEARCH(Q$2, VideoTimeStamps!$E:$E)), 0), 0)), ""))}
A8: FALSE | B8: =IFERROR(__xludf.DUMMYFUNCTION("""COMPUTED_VALUE"""),"Deb") -> Deb | D8: {=IF(OR($B8="", D$2=""), "", IFERROR(INDEX(VideoTimeStamps!$C:$C, MATCH(1, INDEX((VideoTimeStamps!$A:$A=$B8)*ISNUMBER(SEARCH(D$2, VideoTimeStamps!$E:$E)), 0), 0)), ""))} | E8: {=IF(OR($B8="", E$2=""), "", IFERROR(INDEX(VideoTimeStamps!$C:$C, MATCH(1, INDEX((VideoTimeStamps!$A:$A=$B8)*ISNUMBER(SEARCH(E$2, VideoTimeStamps!$E:$E)), 0), 0)), ""))} | F8: {=IF(OR($B8="", F$2=""), "", IFERROR(INDEX(VideoTimeStamps!$C:$C, MATCH(1, INDEX((VideoTimeStamps!$A:$A=$B8)*ISNUMBER(SEARCH(F$2, VideoTimeStamps!$E:$E)), 0), 0)), ""))} | G8: {=IF(OR($B8="", G$2=""), "", IFERROR(INDEX(VideoTimeStamps!$C:$C, MATCH(1, INDEX((VideoTimeStamps!$A:$A=$B8)*ISNUMBER(SEARCH(G$2, VideoTimeStamps!$E:$E)), 0), 0)), ""))} | H8: {=IF(OR($B8="", H$2=""), "", IFERROR(INDEX(VideoTimeStamps!$C:$C, MATCH(1, INDEX((VideoTimeStamps!$A:$A=$B8)*ISNUMBER(SEARCH(H$2, VideoTimeStamps!$E:$E)), 0), 0)), ""))} | I8: {=IF(OR($B8="", I$2=""), "", IFERROR(INDEX(VideoTimeStamps!$C:$C, MATCH(1, INDEX((VideoTimeStamps!$A:$A=$B8)*ISNUMBER(SEARCH(I$2, VideoTimeStamps!$E:$E)), 0), 0)), ""))} | J8: {=IF(OR($B8="", J$2=""), "", IFERROR(INDEX(VideoTimeStamps!$C:$C, MATCH(1, INDEX((VideoTimeStamps!$A:$A=$B8)*ISNUMBER(SEARCH(J$2, VideoTimeStamps!$E:$E)), 0), 0)), ""))} | K8: {=IF(OR($B8="", K$2=""), "", IFERROR(INDEX(VideoTimeStamps!$C:$C, MATCH(1, INDEX((VideoTimeStamps!$A:$A=$B8)*ISNUMBER(SEARCH(K$2, VideoTimeStamps!$E:$E)), 0), 0)), ""))} | ... Q8: {=IF(OR($B8="", Q$2=""), "", IFERROR(INDEX(VideoTimeStamps!$C:$C, MATCH(1, INDEX((VideoTimeStamps!$A:$A=$B8)*ISNUMBER(SEARCH(Q$2, VideoTimeStamps!$E:$E)), 0), 0)), ""))}
A9: FALSE | B9: =IFERROR(__xludf.DUMMYFUNCTION("""COMPUTED_VALUE"""),"Serena") -> Serena | D9: {=IF(OR($B9="", D$2=""), "", IFERROR(INDEX(VideoTimeStamps!$C:$C, MATCH(1, INDEX((VideoTimeStamps!$A:$A=$B9)*ISNUMBER(SEARCH(D$2, VideoTimeStamps!$E:$E)), 0), 0)), ""))} | E9: {=IF(OR($B9="", E$2=""), "", IFERROR(INDEX(VideoTimeStamps!$C:$C, MATCH(1, INDEX((VideoTimeStamps!$A:$A=$B9)*ISNUMBER(SEARCH(E$2, VideoTimeStamps!$E:$E)), 0), 0)), ""))} | F9: {=IF(OR($B9="", F$2=""), "", IFERROR(INDEX(VideoTimeStamps!$C:$C, MATCH(1, INDEX((VideoTimeStamps!$A:$A=$B9)*ISNUMBER(SEARCH(F$2, VideoTimeStamps!$E:$E)), 0), 0)), ""))} | G9: {=IF(OR($B9="", G$2=""), "", IFERROR(INDEX(VideoTimeStamps!$C:$C, MATCH(1, INDEX((VideoTimeStamps!$A:$A=$B9)*ISNUMBER(SEARCH(G$2, VideoTimeStamps!$E:$E)), 0), 0)), ""))} | H9: {=IF(OR($B9="", H$2=""), "", IFERROR(INDEX(VideoTimeStamps!$C:$C, MATCH(1, INDEX((VideoTimeStamps!$A:$A=$B9)*ISNUMBER(SEARCH(H$2, VideoTimeStamps!$E:$E)), 0), 0)), ""))} | I9: {=IF(OR($B9="", I$2=""), "", IFERROR(INDEX(VideoTimeStamps!$C:$C, MATCH(1, INDEX((VideoTimeStamps!$A:$A=$B9)*ISNUMBER(SEARCH(I$2, VideoTimeStamps!$E:$E)), 0), 0)), ""))} | J9: {=IF(OR($B9="", J$2=""), "", IFERROR(INDEX(VideoTimeStamps!$C:$C, MATCH(1, INDEX((VideoTimeStamps!$A:$A=$B9)*ISNUMBER(SEARCH(J$2, VideoTimeStamps!$E:$E)), 0), 0)), ""))} | K9: {=IF(OR($B9="", K$2=""), "", IFERROR(INDEX(VideoTimeStamps!$C:$C, MATCH(1, INDEX((VideoTimeStamps!$A:$A=$B9)*ISNUMBER(SEARCH(K$2, VideoTimeStamps!$E:$E)), 0), 0)), ""))} | ... Q9: {=IF(OR($B9="", Q$2=""), "", IFERROR(INDEX(VideoTimeStamps!$C:$C, MATCH(1, INDEX((VideoTimeStamps!$A:$A=$B9)*ISNUMBER(SEARCH(Q$2, VideoTimeStamps!$E:$E)), 0), 0)), ""))}
A10: FALSE | B10: =IFERROR(__xludf.DUMMYFUNCTION("""COMPUTED_VALUE"""),"singapore.babydiary") -> singapore.babydiary | D10: {=IF(OR($B10="", D$2=""), "", IFERROR(INDEX(VideoTimeStamps!$C:$C, MATCH(1, INDEX((VideoTimeStamps!$A:$A=$B10)*ISNUMBER(SEARCH(D$2, VideoTimeStamps!$E:$E)), 0), 0)), ""))} | E10: {=IF(OR($B10="", E$2=""), "", IFERROR(INDEX(VideoTimeStamps!$C:$C, MATCH(1, INDEX((VideoTimeStamps!$A:$A=$B10)*ISNUMBER(SEARCH(E$2, VideoTimeStamps!$E:$E)), 0), 0)), ""))} | F10: {=IF(OR($B10="", F$2=""), "", IFERROR(INDEX(VideoTimeStamps!$C:$C, MATCH(1, INDEX((VideoTimeStamps!$A:$A=$B10)*ISNUMBER(SEARCH(F$2, VideoTimeStamps!$E:$E)), 0), 0)), ""))} | G10: {=IF(OR($B10="", G$2=""), "", IFERROR(INDEX(VideoTimeStamps!$C:$C, MATCH(1, INDEX((VideoTimeStamps!$A:$A=$B10)*ISNUMBER(SEARCH(G$2, VideoTimeStamps!$E:$E)), 0), 0)), ""))} | H10: {=IF(OR($B10="", H$2=""), "", IFERROR(INDEX(VideoTimeStamps!$C:$C, MATCH(1, INDEX((VideoTimeStamps!$A:$A=$B10)*ISNUMBER(SEARCH(H$2, VideoTimeStamps!$E:$E)), 0), 0)), ""))} | I10: {=IF(OR($B10="", I$2=""), "", IFERROR(INDEX(VideoTimeStamps!$C:$C, MATCH(1, INDEX((VideoTimeStamps!$A:$A=$B10)*ISNUMBER(SEARCH(I$2, VideoTimeStamps!$E:$E)), 0), 0)), ""))} | J10: {=IF(OR($B10="", J$2=""), "", IFERROR(INDEX(VideoTimeStamps!$C:$C, MATCH(1, INDEX((VideoTimeStamps!$A:$A=$B10)*ISNUMBER(SEARCH(J$2, VideoTimeStamps!$E:$E)), 0), 0)), ""))} | K10: {=IF(OR($B10="", K$2=""), "", IFERROR(INDEX(VideoTimeStamps!$C:$C, MATCH(1, INDEX((VideoTimeStamps!$A:$A=$B10)*ISNUMBER(SEARCH(K$2, VideoTimeStamps!$E:$E)), 0), 0)), ""))} | ... Q10: {=IF(OR($B10="", Q$2=""), "", IFERROR(INDEX(VideoTimeStamps!$C:$C, MATCH(1, INDEX((VideoTimeStamps!$A:$A=$B10)*ISNUMBER(SEARCH(Q$2, VideoTimeStamps!$E:$E)), 0), 0)), ""))}
A11: FALSE | B11: =IFERROR(__xludf.DUMMYFUNCTION("""COMPUTED_VALUE"""),"simletseat") -> simletseat | D11: {=IF(OR($B11="", D$2=""), "", IFERROR(INDEX(VideoTimeStamps!$C:$C, MATCH(1, INDEX((VideoTimeStamps!$A:$A=$B11)*ISNUMBER(SEARCH(D$2, VideoTimeStamps!$E:$E)), 0), 0)), ""))} | E11: {=IF(OR($B11="", E$2=""), "", IFERROR(INDEX(VideoTimeStamps!$C:$C, MATCH(1, INDEX((VideoTimeStamps!$A:$A=$B11)*ISNUMBER(SEARCH(E$2, VideoTimeStamps!$E:$E)), 0), 0)), ""))} | F11: {=IF(OR($B11="", F$2=""), "", IFERROR(INDEX(VideoTimeStamps!$C:$C, MATCH(1, INDEX((VideoTimeStamps!$A:$A=$B11)*ISNUMBER(SEARCH(F$2, VideoTimeStamps!$E:$E)), 0), 0)), ""))} | G11: {=IF(OR($B11="", G$2=""), "", IFERROR(INDEX(VideoTimeStamps!$C:$C, MATCH(1, INDEX((VideoTimeStamps!$A:$A=$B11)*ISNUMBER(SEARCH(G$2, VideoTimeStamps!$E:$E)), 0), 0)), ""))} | H11: {=IF(OR($B11="", H$2=""), "", IFERROR(INDEX(VideoTimeStamps!$C:$C, MATCH(1, INDEX((VideoTimeStamps!$A:$A=$B11)*ISNUMBER(SEARCH(H$2, VideoTimeStamps!$E:$E)), 0), 0)), ""))} | I11: {=IF(OR($B11="", I$2=""), "", IFERROR(INDEX(VideoTimeStamps!$C:$C, MATCH(1, INDEX((VideoTimeStamps!$A:$A=$B11)*ISNUMBER(SEARCH(I$2, VideoTimeStamps!$E:$E)), 0), 0)), ""))} | J11: {=IF(OR($B11="", J$2=""), "", IFERROR(INDEX(VideoTimeStamps!$C:$C, MATCH(1, INDEX((VideoTimeStamps!$A:$A=$B11)*ISNUMBER(SEARCH(J$2, VideoTimeStamps!$E:$E)), 0), 0)), ""))} | K11: {=IF(OR($B11="", K$2=""), "", IFERROR(INDEX(VideoTimeStamps!$C:$C, MATCH(1, INDEX((VideoTimeStamps!$A:$A=$B11)*ISNUMBER(SEARCH(K$2, VideoTimeStamps!$E:$E)), 0), 0)), ""))} | ... Q11: {=IF(OR($B11="", Q$2=""), "", IFERROR(INDEX(VideoTimeStamps!$C:$C, MATCH(1, INDEX((VideoTimeStamps!$A:$A=$B11)*ISNUMBER(SEARCH(Q$2, VideoTimeStamps!$E:$E)), 0), 0)), ""))}
A12: FALSE | B12: =IFERROR(__xludf.DUMMYFUNCTION("""COMPUTED_VALUE"""),"Caca Mama") -> Caca Mama | D12: {=IF(OR($B12="", D$2=""), "", IFERROR(INDEX(VideoTimeStamps!$C:$C, MATCH(1, INDEX((VideoTimeStamps!$A:$A=$B12)*ISNUMBER(SEARCH(D$2, VideoTimeStamps!$E:$E)), 0), 0)), ""))} | E12: {=IF(OR($B12="", E$2=""), "", IFERROR(INDEX(VideoTimeStamps!$C:$C, MATCH(1, INDEX((VideoTimeStamps!$A:$A=$B12)*ISNUMBER(SEARCH(E$2, VideoTimeStamps!$E:$E)), 0), 0)), ""))} | F12: {=IF(OR($B12="", F$2=""), "", IFERROR(INDEX(VideoTimeStamps!$C:$C, MATCH(1, INDEX((VideoTimeStamps!$A:$A=$B12)*ISNUMBER(SEARCH(F$2, VideoTimeStamps!$E:$E)), 0), 0)), ""))} | G12: {=IF(OR($B12="", G$2=""), "", IFERROR(INDEX(VideoTimeStamps!$C:$C, MATCH(1, INDEX((VideoTimeStamps!$A:$A=$B12)*ISNUMBER(SEARCH(G$2, VideoTimeStamps!$E:$E)), 0), 0)), ""))} | H12: {=IF(OR($B12="", H$2=""), "", IFERROR(INDEX(VideoTimeStamps!$C:$C, MATCH(1, INDEX((VideoTimeStamps!$A:$A=$B12)*ISNUMBER(SEARCH(H$2, VideoTimeStamps!$E:$E)), 0), 0)), ""))} | I12: {=IF(OR($B12="", I$2=""), "", IFERROR(INDEX(VideoTimeStamps!$C:$C, MATCH(1, INDEX((VideoTimeStamps!$A:$A=$B12)*ISNUMBER(SEARCH(I$2, VideoTimeStamps!$E:$E)), 0), 0)), ""))} | J12: {=IF(OR($B12="", J$2=""), "", IFERROR(INDEX(VideoTimeStamps!$C:$C, MATCH(1, INDEX((VideoTimeStamps!$A:$A=$B12)*ISNUMBER(SEARCH(J$2, VideoTimeStamps!$E:$E)), 0), 0)), ""))} | K12: {=IF(OR($B12="", K$2=""), "", IFERROR(INDEX(VideoTimeStamps!$C:$C, MATCH(1, INDEX((VideoTimeStamps!$A:$A=$B12)*ISNUMBER(SEARCH(K$2, VideoTimeStamps!$E:$E)), 0), 0)), ""))} | ... Q12: {=IF(OR($B12="", Q$2=""), "", IFERROR(INDEX(VideoTimeStamps!$C:$C, MATCH(1, INDEX((VideoTimeStamps!$A:$A=$B12)*ISNUMBER(SEARCH(Q$2, VideoTimeStamps!$E:$E)), 0), 0)), ""))}
A13: FALSE | B13: =IFERROR(__xludf.DUMMYFUNCTION("""COMPUTED_VALUE"""),"Katie") -> Katie | D13: {=IF(OR($B13="", D$2=""), "", IFERROR(INDEX(VideoTimeStamps!$C:$C, MATCH(1, INDEX((VideoTimeStamps!$A:$A=$B13)*ISNUMBER(SEARCH(D$2, VideoTimeStamps!$E:$E)), 0), 0)), ""))} | E13: {=IF(OR($B13="", E$2=""), "", IFERROR(INDEX(VideoTimeStamps!$C:$C, MATCH(1, INDEX((VideoTimeStamps!$A:$A=$B13)*ISNUMBER(SEARCH(E$2, VideoTimeStamps!$E:$E)), 0), 0)), ""))} | F13: {=IF(OR($B13="", F$2=""), "", IFERROR(INDEX(VideoTimeStamps!$C:$C, MATCH(1, INDEX((VideoTimeStamps!$A:$A=$B13)*ISNUMBER(SEARCH(F$2, VideoTimeStamps!$E:$E)), 0), 0)), ""))} | G13: {=IF(OR($B13="", G$2=""), "", IFERROR(INDEX(VideoTimeStamps!$C:$C, MATCH(1, INDEX((VideoTimeStamps!$A:$A=$B13)*ISNUMBER(SEARCH(G$2, VideoTimeStamps!$E:$E)), 0), 0)), ""))} | H13: {=IF(OR($B13="", H$2=""), "", IFERROR(INDEX(VideoTimeStamps!$C:$C, MATCH(1, INDEX((VideoTimeStamps!$A:$A=$B13)*ISNUMBER(SEARCH(H$2, VideoTimeStamps!$E:$E)), 0), 0)), ""))} | I13: {=IF(OR($B13="", I$2=""), "", IFERROR(INDEX(VideoTimeStamps!$C:$C, MATCH(1, INDEX((VideoTimeStamps!$A:$A=$B13)*ISNUMBER(SEARCH(I$2, VideoTimeStamps!$E:$E)), 0), 0)), ""))} | J13: {=IF(OR($B13="", J$2=""), "", IFERROR(INDEX(VideoTimeStamps!$C:$C, MATCH(1, INDEX((VideoTimeStamps!$A:$A=$B13)*ISNUMBER(SEARCH(J$2, VideoTimeStamps!$E:$E)), 0), 0)), ""))} | K13: {=IF(OR($B13="", K$2=""), "", IFERROR(INDEX(VideoTimeStamps!$C:$C, MATCH(1, INDEX((VideoTimeStamps!$A:$A=$B13)*ISNUMBER(SEARCH(K$2, VideoTimeStamps!$E:$E)), 0), 0)), ""))} | ... Q13: {=IF(OR($B13="", Q$2=""), "", IFERROR(INDEX(VideoTimeStamps!$C:$C, MATCH(1, INDEX((VideoTimeStamps!$A:$A=$B13)*ISNUMBER(SEARCH(Q$2, VideoTimeStamps!$E:$E)), 0), 0)), ""))}
A14: FALSE | B14: =IFERROR(__xludf.DUMMYFUNCTION("""COMPUTED_VALUE"""),"Kamisin") -> Kamisin | D14: {=IF(OR($B14="", D$2=""), "", IFERROR(INDEX(VideoTimeStamps!$C:$C, MATCH(1, INDEX((VideoTimeStamps!$A:$A=$B14)*ISNUMBER(SEARCH(D$2, VideoTimeStamps!$E:$E)), 0), 0)), ""))} | E14: {=IF(OR($B14="", E$2=""), "", IFERROR(INDEX(VideoTimeStamps!$C:$C, MATCH(1, INDEX((VideoTimeStamps!$A:$A=$B14)*ISNUMBER(SEARCH(E$2, VideoTimeStamps!$E:$E)), 0), 0)), ""))} | F14: {=IF(OR($B14="", F$2=""), "", IFERROR(INDEX(VideoTimeStamps!$C:$C, MATCH(1, INDEX((VideoTimeStamps!$A:$A=$B14)*ISNUMBER(SEARCH(F$2, VideoTimeStamps!$E:$E)), 0), 0)), ""))} | G14: {=IF(OR($B14="", G$2=""), "", IFERROR(INDEX(VideoTimeStamps!$C:$C, MATCH(1, INDEX((VideoTimeStamps!$A:$A=$B14)*ISNUMBER(SEARCH(G$2, VideoTimeStamps!$E:$E)), 0), 0)), ""))} | H14: {=IF(OR($B14="", H$2=""), "", IFERROR(INDEX(VideoTimeStamps!$C:$C, MATCH(1, INDEX((VideoTimeStamps!$A:$A=$B14)*ISNUMBER(SEARCH(H$2, VideoTimeStamps!$E:$E)), 0), 0)), ""))} | I14: {=IF(OR($B14="", I$2=""), "", IFERROR(INDEX(VideoTimeStamps!$C:$C, MATCH(1, INDEX((VideoTimeStamps!$A:$A=$B14)*ISNUMBER(SEARCH(I$2, VideoTimeStamps!$E:$E)), 0), 0)), ""))} | J14: {=IF(OR($B14="", J$2=""), "", IFERROR(INDEX(VideoTimeStamps!$C:$C, MATCH(1, INDEX((VideoTimeStamps!$A:$A=$B14)*ISNUMBER(SEARCH(J$2, VideoTimeStamps!$E:$E)), 0), 0)), ""))} | K14: {=IF(OR($B14="", K$2=""), "", IFERROR(INDEX(VideoTimeStamps!$C:$C, MATCH(1, INDEX((VideoTimeStamps!$A:$A=$B14)*ISNUMBER(SEARCH(K$2, VideoTimeStamps!$E:$E)), 0), 0)), ""))} | ... Q14: {=IF(OR($B14="", Q$2=""), "", IFERROR(INDEX(VideoTimeStamps!$C:$C, MATCH(1, INDEX((VideoTimeStamps!$A:$A=$B14)*ISNUMBER(SEARCH(Q$2, VideoTimeStamps!$E:$E)), 0), 0)), ""))}
A15: FALSE | B15: =IFERROR(__xludf.DUMMYFUNCTION("""COMPUTED_VALUE"""),"Dadalam") -> Dadalam | D15: {=IF(OR($B15="", D$2=""), "", IFERROR(INDEX(VideoTimeStamps!$C:$C, MATCH(1, INDEX((VideoTimeStamps!$A:$A=$B15)*ISNUMBER(SEARCH(D$2, VideoTimeStamps!$E:$E)), 0), 0)), ""))} | E15: {=IF(OR($B15="", E$2=""), "", IFERROR(INDEX(VideoTimeStamps!$C:$C, MATCH(1, INDEX((VideoTimeStamps!$A:$A=$B15)*ISNUMBER(SEARCH(E$2, VideoTimeStamps!$E:$E)), 0), 0)), ""))} | F15: {=IF(OR($B15="", F$2=""), "", IFERROR(INDEX(VideoTimeStamps!$C:$C, MATCH(1, INDEX((VideoTimeStamps!$A:$A=$B15)*ISNUMBER(SEARCH(F$2, VideoTimeStamps!$E:$E)), 0), 0)), ""))} | G15: {=IF(OR($B15="", G$2=""), "", IFERROR(INDEX(VideoTimeStamps!$C:$C, MATCH(1, INDEX((VideoTimeStamps!$A:$A=$B15)*ISNUMBER(SEARCH(G$2, VideoTimeStamps!$E:$E)), 0), 0)), ""))} | H15: {=IF(OR($B15="", H$2=""), "", IFERROR(INDEX(VideoTimeStamps!$C:$C, MATCH(1, INDEX((VideoTimeStamps!$A:$A=$B15)*ISNUMBER(SEARCH(H$2, VideoTimeStamps!$E:$E)), 0), 0)), ""))} | I15: {=IF(OR($B15="", I$2=""), "", IFERROR(INDEX(VideoTimeStamps!$C:$C, MATCH(1, INDEX((VideoTimeStamps!$A:$A=$B15)*ISNUMBER(SEARCH(I$2, VideoTimeStamps!$E:$E)), 0), 0)), ""))} | J15: {=IF(OR($B15="", J$2=""), "", IFERROR(INDEX(VideoTimeStamps!$C:$C, MATCH(1, INDEX((VideoTimeStamps!$A:$A=$B15)*ISNUMBER(SEARCH(J$2, VideoTimeStamps!$E:$E)), 0), 0)), ""))} | K15: {=IF(OR($B15="", K$2=""), "", IFERROR(INDEX(VideoTimeStamps!$C:$C, MATCH(1, INDEX((VideoTimeStamps!$A:$A=$B15)*ISNUMBER(SEARCH(K$2, VideoTimeStamps!$E:$E)), 0), 0)), ""))} | ... Q15: {=IF(OR($B15="", Q$2=""), "", IFERROR(INDEX(VideoTimeStamps!$C:$C, MATCH(1, INDEX((VideoTimeStamps!$A:$A=$B15)*ISNUMBER(SEARCH(Q$2, VideoTimeStamps!$E:$E)), 0), 0)), ""))}
A16: FALSE | B16: =IFERROR(__xludf.DUMMYFUNCTION("""COMPUTED_VALUE""")," Iamsabrinalau") -> Iamsabrinalau | D16: {=IF(OR($B16="", D$2=""), "", IFERROR(INDEX(VideoTimeStamps!$C:$C, MATCH(1, INDEX((VideoTimeStamps!$A:$A=$B16)*ISNUMBER(SEARCH(D$2, VideoTimeStamps!$E:$E)), 0), 0)), ""))} | E16: {=IF(OR($B16="", E$2=""), "", IFERROR(INDEX(VideoTimeStamps!$C:$C, MATCH(1, INDEX((VideoTimeStamps!$A:$A=$B16)*ISNUMBER(SEARCH(E$2, VideoTimeStamps!$E:$E)), 0), 0)), ""))} | F16: {=IF(OR($B16="", F$2=""), "", IFERROR(INDEX(VideoTimeStamps!$C:$C, MATCH(1, INDEX((VideoTimeStamps!$A:$A=$B16)*ISNUMBER(SEARCH(F$2, VideoTimeStamps!$E:$E)), 0), 0)), ""))} | G16: {=IF(OR($B16="", G$2=""), "", IFERROR(INDEX(VideoTimeStamps!$C:$C, MATCH(1, INDEX((VideoTimeStamps!$A:$A=$B16)*ISNUMBER(SEARCH(G$2, VideoTimeStamps!$E:$E)), 0), 0)), ""))} | H16: {=IF(OR($B16="", H$2=""), "", IFERROR(INDEX(VideoTimeStamps!$C:$C, MATCH(1, INDEX((VideoTimeStamps!$A:$A=$B16)*ISNUMBER(SEARCH(H$2, VideoTimeStamps!$E:$E)), 0), 0)), ""))} | I16: {=IF(OR($B16="", I$2=""), "", IFERROR(INDEX(VideoTimeStamps!$C:$C, MATCH(1, INDEX((VideoTimeStamps!$A:$A=$B16)*ISNUMBER(SEARCH(I$2, VideoTimeStamps!$E:$E)), 0), 0)), ""))} | J16: {=IF(OR($B16="", J$2=""), "", IFERROR(INDEX(VideoTimeStamps!$C:$C, MATCH(1, INDEX((VideoTimeStamps!$A:$A=$B16)*ISNUMBER(SEARCH(J$2, VideoTimeStamps!$E:$E)), 0), 0)), ""))} | K16: {=IF(OR($B16="", K$2=""), "", IFERROR(INDEX(VideoTimeStamps!$C:$C, MATCH(1, INDEX((VideoTimeStamps!$A:$A=$B16)*ISNUMBER(SEARCH(K$2, VideoTimeStamps!$E:$E)), 0), 0)), ""))} | ... Q16: {=IF(OR($B16="", Q$2=""), "", IFERROR(INDEX(VideoTimeStamps!$C:$C, MATCH(1, INDEX((VideoTimeStamps!$A:$A=$B16)*ISNUMBER(SEARCH(Q$2, VideoTimeStamps!$E:$E)), 0), 0)), ""))}
A17: FALSE | B17: =IFERROR(__xludf.DUMMYFUNCTION("""COMPUTED_VALUE"""),"3pigpigpig") -> 3pigpigpig | D17: {=IF(OR($B17="", D$2=""), "", IFERROR(INDEX(VideoTimeStamps!$C:$C, MATCH(1, INDEX((VideoTimeStamps!$A:$A=$B17)*ISNUMBER(SEARCH(D$2, VideoTimeStamps!$E:$E)), 0), 0)), ""))} | E17: {=IF(OR($B17="", E$2=""), "", IFERROR(INDEX(VideoTimeStamps!$C:$C, MATCH(1, INDEX((VideoTimeStamps!$A:$A=$B17)*ISNUMBER(SEARCH(E$2, VideoTimeStamps!$E:$E)), 0), 0)), ""))} | F17: {=IF(OR($B17="", F$2=""), "", IFERROR(INDEX(VideoTimeStamps!$C:$C, MATCH(1, INDEX((VideoTimeStamps!$A:$A=$B17)*ISNUMBER(SEARCH(F$2, VideoTimeStamps!$E:$E)), 0), 0)), ""))} | G17: {=IF(OR($B17="", G$2=""), "", IFERROR(INDEX(VideoTimeStamps!$C:$C, MATCH(1, INDEX((VideoTimeStamps!$A:$A=$B17)*ISNUMBER(SEARCH(G$2, VideoTimeStamps!$E:$E)), 0), 0)), ""))} | H17: {=IF(OR($B17="", H$2=""), "", IFERROR(INDEX(VideoTimeStamps!$C:$C, MATCH(1, INDEX((VideoTimeStamps!$A:$A=$B17)*ISNUMBER(SEARCH(H$2, VideoTimeStamps!$E:$E)), 0), 0)), ""))} | I17: {=IF(OR($B17="", I$2=""), "", IFERROR(INDEX(VideoTimeStamps!$C:$C, MATCH(1, INDEX((VideoTimeStamps!$A:$A=$B17)*ISNUMBER(SEARCH(I$2, VideoTimeStamps!$E:$E)), 0), 0)), ""))} | J17: {=IF(OR($B17="", J$2=""), "", IFERROR(INDEX(VideoTimeStamps!$C:$C, MATCH(1, INDEX((VideoTimeStamps!$A:$A=$B17)*ISNUMBER(SEARCH(J$2, VideoTimeStamps!$E:$E)), 0), 0)), ""))} | K17: {=IF(OR($B17="", K$2=""), "", IFERROR(INDEX(VideoTimeStamps!$C:$C, MATCH(1, INDEX((VideoTimeStamps!$A:$A=$B17)*ISNUMBER(SEARCH(K$2, VideoTimeStamps!$E:$E)), 0), 0)), ""))} | ... Q17: {=IF(OR($B17="", Q$2=""), "", IFERROR(INDEX(VideoTimeStamps!$C:$C, MATCH(1, INDEX((VideoTimeStamps!$A:$A=$B17)*ISNUMBER(SEARCH(Q$2, VideoTimeStamps!$E:$E)), 0), 0)), ""))}
A18: FALSE | B18: =IFERROR(__xludf.DUMMYFUNCTION("""COMPUTED_VALUE"""),"yanxcky") -> yanxcky | D18: {=IF(OR($B18="", D$2=""), "", IFERROR(INDEX(VideoTimeStamps!$C:$C, MATCH(1, INDEX((VideoTimeStamps!$A:$A=$B18)*ISNUMBER(SEARCH(D$2, VideoTimeStamps!$E:$E)), 0), 0)), ""))} | E18: {=IF(OR($B18="", E$2=""), "", IFERROR(INDEX(VideoTimeStamps!$C:$C, MATCH(1, INDEX((VideoTimeStamps!$A:$A=$B18)*ISNUMBER(SEARCH(E$2, VideoTimeStamps!$E:$E)), 0), 0)), ""))} | F18: {=IF(OR($B18="", F$2=""), "", IFERROR(INDEX(VideoTimeStamps!$C:$C, MATCH(1, INDEX((VideoTimeStamps!$A:$A=$B18)*ISNUMBER(SEARCH(F$2, VideoTimeStamps!$E:$E)), 0), 0)), ""))} | G18: {=IF(OR($B18="", G$2=""), "", IFERROR(INDEX(VideoTimeStamps!$C:$C, MATCH(1, INDEX((VideoTimeStamps!$A:$A=$B18)*ISNUMBER(SEARCH(G$2, VideoTimeStamps!$E:$E)), 0), 0)), ""))} | H18: {=IF(OR($B18="", H$2=""), "", IFERROR(INDEX(VideoTimeStamps!$C:$C, MATCH(1, INDEX((VideoTimeStamps!$A:$A=$B18)*ISNUMBER(SEARCH(H$2, VideoTimeStamps!$E:$E)), 0), 0)), ""))} | I18: {=IF(OR($B18="", I$2=""), "", IFERROR(INDEX(VideoTimeStamps!$C:$C, MATCH(1, INDEX((VideoTimeStamps!$A:$A=$B18)*ISNUMBER(SEARCH(I$2, VideoTimeStamps!$E:$E)), 0), 0)), ""))} | J18: {=IF(OR($B18="", J$2=""), "", IFERROR(INDEX(VideoTimeStamps!$C:$C, MATCH(1, INDEX((VideoTimeStamps!$A:$A=$B18)*ISNUMBER(SEARCH(J$2, VideoTimeStamps!$E:$E)), 0), 0)), ""))} | K18: {=IF(OR($B18="", K$2=""), "", IFERROR(INDEX(VideoTimeStamps!$C:$C, MATCH(1, INDEX((VideoTimeStamps!$A:$A=$B18)*ISNUMBER(SEARCH(K$2, VideoTimeStamps!$E:$E)), 0), 0)), ""))} | ... Q18: {=IF(OR($B18="", Q$2=""), "", IFERROR(INDEX(VideoTimeStamps!$C:$C, MATCH(1, INDEX((VideoTimeStamps!$A:$A=$B18)*ISNUMBER(SEARCH(Q$2, VideoTimeStamps!$E:$E)), 0), 0)), ""))}
A19: FALSE | B19: =IFERROR(__xludf.DUMMYFUNCTION("""COMPUTED_VALUE"""),"Scarlett") -> Scarlett | D19: {=IF(OR($B19="", D$2=""), "", IFERROR(INDEX(VideoTimeStamps!$C:$C, MATCH(1, INDEX((VideoTimeStamps!$A:$A=$B19)*ISNUMBER(SEARCH(D$2, VideoTimeStamps!$E:$E)), 0), 0)), ""))} | E19: {=IF(OR($B19="", E$2=""), "", IFERROR(INDEX(VideoTimeStamps!$C:$C, MATCH(1, INDEX((VideoTimeStamps!$A:$A=$B19)*ISNUMBER(SEARCH(E$2, VideoTimeStamps!$E:$E)), 0), 0)), ""))} | F19: {=IF(OR($B19="", F$2=""), "", IFERROR(INDEX(VideoTimeStamps!$C:$C, MATCH(1, INDEX((VideoTimeStamps!$A:$A=$B19)*ISNUMBER(SEARCH(F$2, VideoTimeStamps!$E:$E)), 0), 0)), ""))} | G19: {=IF(OR($B19="", G$2=""), "", IFERROR(INDEX(VideoTimeStamps!$C:$C, MATCH(1, INDEX((VideoTimeStamps!$A:$A=$B19)*ISNUMBER(SEARCH(G$2, VideoTimeStamps!$E:$E)), 0), 0)), ""))} | H19: {=IF(OR($B19="", H$2=""), "", IFERROR(INDEX(VideoTimeStamps!$C:$C, MATCH(1, INDEX((VideoTimeStamps!$A:$A=$B19)*ISNUMBER(SEARCH(H$2, VideoTimeStamps!$E:$E)), 0), 0)), ""))} | I19: {=IF(OR($B19="", I$2=""), "", IFERROR(INDEX(VideoTimeStamps!$C:$C, MATCH(1, INDEX((VideoTimeStamps!$A:$A=$B19)*ISNUMBER(SEARCH(I$2, VideoTimeStamps!$E:$E)), 0), 0)), ""))} | J19: {=IF(OR($B19="", J$2=""), "", IFERROR(INDEX(VideoTimeStamps!$C:$C, MATCH(1, INDEX((VideoTimeStamps!$A:$A=$B19)*ISNUMBER(SEARCH(J$2, VideoTimeStamps!$E:$E)), 0), 0)), ""))} | K19: {=IF(OR($B19="", K$2=""), "", IFERROR(INDEX(VideoTimeStamps!$C:$C, MATCH(1, INDEX((VideoTimeStamps!$A:$A=$B19)*ISNUMBER(SEARCH(K$2, VideoTimeStamps!$E:$E)), 0), 0)), ""))} | ... Q19: {=IF(OR($B19="", Q$2=""), "", IFERROR(INDEX(VideoTimeStamps!$C:$C, MATCH(1, INDEX((VideoTimeStamps!$A:$A=$B19)*ISNUMBER(SEARCH(Q$2, VideoTimeStamps!$E:$E)), 0), 0)), ""))}
A20: FALSE | B20: =IFERROR(__xludf.DUMMYFUNCTION("""COMPUTED_VALUE"""),"Yeung3kids") -> Yeung3kids | D20: {=IF(OR($B20="", D$2=""), "", IFERROR(INDEX(VideoTimeStamps!$C:$C, MATCH(1, INDEX((VideoTimeStamps!$A:$A=$B20)*ISNUMBER(SEARCH(D$2, VideoTimeStamps!$E:$E)), 0), 0)), ""))} | E20: {=IF(OR($B20="", E$2=""), "", IFERROR(INDEX(VideoTimeStamps!$C:$C, MATCH(1, INDEX((VideoTimeStamps!$A:$A=$B20)*ISNUMBER(SEARCH(E$2, VideoTimeStamps!$E:$E)), 0), 0)), ""))} | F20: {=IF(OR($B20="", F$2=""), "", IFERROR(INDEX(VideoTimeStamps!$C:$C, MATCH(1, INDEX((VideoTimeStamps!$A:$A=$B20)*ISNUMBER(SEARCH(F$2, VideoTimeStamps!$E:$E)), 0), 0)), ""))} | G20: {=IF(OR($B20="", G$2=""), "", IFERROR(INDEX(VideoTimeStamps!$C:$C, MATCH(1, INDEX((VideoTimeStamps!$A:$A=$B20)*ISNUMBER(SEARCH(G$2, VideoTimeStamps!$E:$E)), 0), 0)), ""))} | H20: {=IF(OR($B20="", H$2=""), "", IFERROR(INDEX(VideoTimeStamps!$C:$C, MATCH(1, INDEX((VideoTimeStamps!$A:$A=$B20)*ISNUMBER(SEARCH(H$2, VideoTimeStamps!$E:$E)), 0), 0)), ""))} | I20: {=IF(OR($B20="", I$2=""), "", IFERROR(INDEX(VideoTimeStamps!$C:$C, MATCH(1, INDEX((VideoTimeStamps!$A:$A=$B20)*ISNUMBER(SEARCH(I$2, VideoTimeStamps!$E:$E)), 0), 0)), ""))} | J20: {=IF(OR($B20="", J$2=""), "", IFERROR(INDEX(VideoTimeStamps!$C:$C, MATCH(1, INDEX((VideoTimeStamps!$A:$A=$B20)*ISNUMBER(SEARCH(J$2, VideoTimeStamps!$E:$E)), 0), 0)), ""))} | K20: {=IF(OR($B20="", K$2=""), "", IFERROR(INDEX(VideoTimeStamps!$C:$C, MATCH(1, INDEX((VideoTimeStamps!$A:$A=$B20)*ISNUMBER(SEARCH(K$2, VideoTimeStamps!$E:$E)), 0), 0)), ""))} | ... Q20: {=IF(OR($B20="", Q$2=""), "", IFERROR(INDEX(VideoTimeStamps!$C:$C, MATCH(1, INDEX((VideoTimeStamps!$A:$A=$B20)*ISNUMBER(SEARCH(Q$2, VideoTimeStamps!$E:$E)), 0), 0)), ""))}
A21: FALSE | B21: =IFERROR(__xludf.DUMMYFUNCTION("""COMPUTED_VALUE"""),"Chan") -> Chan | D21: {=IF(OR($B21="", D$2=""), "", IFERROR(INDEX(VideoTimeStamps!$C:$C, MATCH(1, INDEX((VideoTimeStamps!$A:$A=$B21)*ISNUMBER(SEARCH(D$2, VideoTimeStamps!$E:$E)), 0), 0)), ""))} | E21: {=IF(OR($B21="", E$2=""), "", IFERROR(INDEX(VideoTimeStamps!$C:$C, MATCH(1, INDEX((VideoTimeStamps!$A:$A=$B21)*ISNUMBER(SEARCH(E$2, VideoTimeStamps!$E:$E)), 0), 0)), ""))} | F21: {=IF(OR($B21="", F$2=""), "", IFERROR(INDEX(VideoTimeStamps!$C:$C, MATCH(1, INDEX((VideoTimeStamps!$A:$A=$B21)*ISNUMBER(SEARCH(F$2, VideoTimeStamps!$E:$E)), 0), 0)), ""))} | G21: {=IF(OR($B21="", G$2=""), "", IFERROR(INDEX(VideoTimeStamps!$C:$C, MATCH(1, INDEX((VideoTimeStamps!$A:$A=$B21)*ISNUMBER(SEARCH(G$2, VideoTimeStamps!$E:$E)), 0), 0)), ""))} | H21: {=IF(OR($B21="", H$2=""), "", IFERROR(INDEX(VideoTimeStamps!$C:$C, MATCH(1, INDEX((VideoTimeStamps!$A:$A=$B21)*ISNUMBER(SEARCH(H$2, VideoTimeStamps!$E:$E)), 0), 0)), ""))} | I21: {=IF(OR($B21="", I$2=""), "", IFERROR(INDEX(VideoTimeStamps!$C:$C, MATCH(1, INDEX((VideoTimeStamps!$A:$A=$B21)*ISNUMBER(SEARCH(I$2, VideoTimeStamps!$E:$E)), 0), 0)), ""))} | J21: {=IF(OR($B21="", J$2=""), "", IFERROR(INDEX(VideoTimeStamps!$C:$C, MATCH(1, INDEX((VideoTimeStamps!$A:$A=$B21)*ISNUMBER(SEARCH(J$2, VideoTimeStamps!$E:$E)), 0), 0)), ""))} | K21: {=IF(OR($B21="", K$2=""), "", IFERROR(INDEX(VideoTimeStamps!$C:$C, MATCH(1, INDEX((VideoTimeStamps!$A:$A=$B21)*ISNUMBER(SEARCH(K$2, VideoTimeStamps!$E:$E)), 0), 0)), ""))} | ... Q21: {=IF(OR($B21="", Q$2=""), "", IFERROR(INDEX(VideoTimeStamps!$C:$C, MATCH(1, INDEX((VideoTimeStamps!$A:$A=$B21)*ISNUMBER(SEARCH(Q$2, VideoTimeStamps!$E:$E)), 0), 0)), ""))}
A22: FALSE | D22: {=IF(OR($B22="", D$2=""), "", IFERROR(INDEX(VideoTimeStamps!$C:$C, MATCH(1, INDEX((VideoTimeStamps!$A:$A=$B22)*ISNUMBER(SEARCH(D$2, VideoTimeStamps!$E:$E)), 0), 0)), ""))} | E22: {=IF(OR($B22="", E$2=""), "", IFERROR(INDEX(VideoTimeStamps!$C:$C, MATCH(1, INDEX((VideoTimeStamps!$A:$A=$B22)*ISNUMBER(SEARCH(E$2, VideoTimeStamps!$E:$E)), 0), 0)), ""))} | F22: {=IF(OR($B22="", F$2=""), "", IFERROR(INDEX(VideoTimeStamps!$C:$C, MATCH(1, INDEX((VideoTimeStamps!$A:$A=$B22)*ISNUMBER(SEARCH(F$2, VideoTimeStamps!$E:$E)), 0), 0)), ""))} | G22: {=IF(OR($B22="", G$2=""), "", IFERROR(INDEX(VideoTimeStamps!$C:$C, MATCH(1, INDEX((VideoTimeStamps!$A:$A=$B22)*ISNUMBER(SEARCH(G$2, VideoTimeStamps!$E:$E)), 0), 0)), ""))} | H22: {=IF(OR($B22="", H$2=""), "", IFERROR(INDEX(VideoTimeStamps!$C:$C, MATCH(1, INDEX((VideoTimeStamps!$A:$A=$B22)*ISNUMBER(SEARCH(H$2, VideoTimeStamps!$E:$E)), 0), 0)), ""))} | I22: {=IF(OR($B22="", I$2=""), "", IFERROR(INDEX(VideoTimeStamps!$C:$C, MATCH(1, INDEX((VideoTimeStamps!$A:$A=$B22)*ISNUMBER(SEARCH(I$2, VideoTimeStamps!$E:$E)), 0), 0)), ""))} | J22: {=IF(OR($B22="", J$2=""), "", IFERROR(INDEX(VideoTimeStamps!$C:$C, MATCH(1, INDEX((VideoTimeStamps!$A:$A=$B22)*ISNUMBER(SEARCH(J$2, VideoTimeStamps!$E:$E)), 0), 0)), ""))} | K22: {=IF(OR($B22="", K$2=""), "", IFERROR(INDEX(VideoTimeStamps!$C:$C, MATCH(1, INDEX((VideoTimeStamps!$A:$A=$B22)*ISNUMBER(SEARCH(K$2, VideoTimeStamps!$E:$E)), 0), 0)), ""))} | ... Q22: {=IF(OR($B22="", Q$2=""), "", IFERROR(INDEX(VideoTimeStamps!$C:$C, MATCH(1, INDEX((VideoTimeStamps!$A:$A=$B22)*ISNUMBER(SEARCH(Q$2, VideoTimeStamps!$E:$E)), 0), 0)), ""))}
A23: FALSE | D23: {=IF(OR($B23="", D$2=""), "", IFERROR(INDEX(VideoTimeStamps!$C:$C, MATCH(1, INDEX((VideoTimeStamps!$A:$A=$B23)*ISNUMBER(SEARCH(D$2, VideoTimeStamps!$E:$E)), 0), 0)), ""))} | E23: {=IF(OR($B23="", E$2=""), "", IFERROR(INDEX(VideoTimeStamps!$C:$C, MATCH(1, INDEX((VideoTimeStamps!$A:$A=$B23)*ISNUMBER(SEARCH(E$2, VideoTimeStamps!$E:$E)), 0), 0)), ""))} | F23: {=IF(OR($B23="", F$2=""), "", IFERROR(INDEX(VideoTimeStamps!$C:$C, MATCH(1, INDEX((VideoTimeStamps!$A:$A=$B23)*ISNUMBER(SEARCH(F$2, VideoTimeStamps!$E:$E)), 0), 0)), ""))} | G23: {=IF(OR($B23="", G$2=""), "", IFERROR(INDEX(VideoTimeStamps!$C:$C, MATCH(1, INDEX((VideoTimeStamps!$A:$A=$B23)*ISNUMBER(SEARCH(G$2, VideoTimeStamps!$E:$E)), 0), 0)), ""))} | H23: {=IF(OR($B23="", H$2=""), "", IFERROR(INDEX(VideoTimeStamps!$C:$C, MATCH(1, INDEX((VideoTimeStamps!$A:$A=$B23)*ISNUMBER(SEARCH(H$2, VideoTimeStamps!$E:$E)), 0), 0)), ""))} | I23: {=IF(OR($B23="", I$2=""), "", IFERROR(INDEX(VideoTimeStamps!$C:$C, MATCH(1, INDEX((VideoTimeStamps!$A:$A=$B23)*ISNUMBER(SEARCH(I$2, VideoTimeStamps!$E:$E)), 0), 0)), ""))} | J23: {=IF(OR($B23="", J$2=""), "", IFERROR(INDEX(VideoTimeStamps!$C:$C, MATCH(1, INDEX((VideoTimeStamps!$A:$A=$B23)*ISNUMBER(SEARCH(J$2, VideoTimeStamps!$E:$E)), 0), 0)), ""))} | K23: {=IF(OR($B23="", K$2=""), "", IFERROR(INDEX(VideoTimeStamps!$C:$C, MATCH(1, INDEX((VideoTimeStamps!$A:$A=$B23)*ISNUMBER(SEARCH(K$2, VideoTimeStamps!$E:$E)), 0), 0)), ""))} | ... Q23: {=IF(OR($B23="", Q$2=""), "", IFERROR(INDEX(VideoTimeStamps!$C:$C, MATCH(1, INDEX((VideoTimeStamps!$A:$A=$B23)*ISNUMBER(SEARCH(Q$2, VideoTimeStamps!$E:$E)), 0), 0)), ""))}
A24: FALSE | D24: {=IF(OR($B24="", D$2=""), "", IFERROR(INDEX(VideoTimeStamps!$C:$C, MATCH(1, INDEX((VideoTimeStamps!$A:$A=$B24)*ISNUMBER(SEARCH(D$2, VideoTimeStamps!$E:$E)), 0), 0)), ""))} | E24: {=IF(OR($B24="", E$2=""), "", IFERROR(INDEX(VideoTimeStamps!$C:$C, MATCH(1, INDEX((VideoTimeStamps!$A:$A=$B24)*ISNUMBER(SEARCH(E$2, VideoTimeStamps!$E:$E)), 0), 0)), ""))} | F24: {=IF(OR($B24="", F$2=""), "", IFERROR(INDEX(VideoTimeStamps!$C:$C, MATCH(1, INDEX((VideoTimeStamps!$A:$A=$B24)*ISNUMBER(SEARCH(F$2, VideoTimeStamps!$E:$E)), 0), 0)), ""))} | G24: {=IF(OR($B24="", G$2=""), "", IFERROR(INDEX(VideoTimeStamps!$C:$C, MATCH(1, INDEX((VideoTimeStamps!$A:$A=$B24)*ISNUMBER(SEARCH(G$2, VideoTimeStamps!$E:$E)), 0), 0)), ""))} | H24: {=IF(OR($B24="", H$2=""), "", IFERROR(INDEX(VideoTimeStamps!$C:$C, MATCH(1, INDEX((VideoTimeStamps!$A:$A=$B24)*ISNUMBER(SEARCH(H$2, VideoTimeStamps!$E:$E)), 0), 0)), ""))} | I24: {=IF(OR($B24="", I$2=""), "", IFERROR(INDEX(VideoTimeStamps!$C:$C, MATCH(1, INDEX((VideoTimeStamps!$A:$A=$B24)*ISNUMBER(SEARCH(I$2, VideoTimeStamps!$E:$E)), 0), 0)), ""))} | J24: {=IF(OR($B24="", J$2=""), "", IFERROR(INDEX(VideoTimeStamps!$C:$C, MATCH(1, INDEX((VideoTimeStamps!$A:$A=$B24)*ISNUMBER(SEARCH(J$2, VideoTimeStamps!$E:$E)), 0), 0)), ""))} | K24: {=IF(OR($B24="", K$2=""), "", IFERROR(INDEX(VideoTimeStamps!$C:$C, MATCH(1, INDEX((VideoTimeStamps!$A:$A=$B24)*ISNUMBER(SEARCH(K$2, VideoTimeStamps!$E:$E)), 0), 0)), ""))} | ... Q24: {=IF(OR($B24="", Q$2=""), "", IFERROR(INDEX(VideoTimeStamps!$C:$C, MATCH(1, INDEX((VideoTimeStamps!$A:$A=$B24)*ISNUMBER(SEARCH(Q$2, VideoTimeStamps!$E:$E)), 0), 0)), ""))}
A25: FALSE | D25: {=IF(OR($B25="", D$2=""), "", IFERROR(INDEX(VideoTimeStamps!$C:$C, MATCH(1, INDEX((VideoTimeStamps!$A:$A=$B25)*ISNUMBER(SEARCH(D$2, VideoTimeStamps!$E:$E)), 0), 0)), ""))} | E25: {=IF(OR($B25="", E$2=""), "", IFERROR(INDEX(VideoTimeStamps!$C:$C, MATCH(1, INDEX((VideoTimeStamps!$A:$A=$B25)*ISNUMBER(SEARCH(E$2, VideoTimeStamps!$E:$E)), 0), 0)), ""))} | F25: {=IF(OR($B25="", F$2=""), "", IFERROR(INDEX(VideoTimeStamps!$C:$C, MATCH(1, INDEX((VideoTimeStamps!$A:$A=$B25)*ISNUMBER(SEARCH(F$2, VideoTimeStamps!$E:$E)), 0), 0)), ""))} | G25: {=IF(OR($B25="", G$2=""), "", IFERROR(INDEX(VideoTimeStamps!$C:$C, MATCH(1, INDEX((VideoTimeStamps!$A:$A=$B25)*ISNUMBER(SEARCH(G$2, VideoTimeStamps!$E:$E)), 0), 0)), ""))} | H25: {=IF(OR($B25="", H$2=""), "", IFERROR(INDEX(VideoTimeStamps!$C:$C, MATCH(1, INDEX((VideoTimeStamps!$A:$A=$B25)*ISNUMBER(SEARCH(H$2, VideoTimeStamps!$E:$E)), 0), 0)), ""))} | I25: {=IF(OR($B25="", I$2=""), "", IFERROR(INDEX(VideoTimeStamps!$C:$C, MATCH(1, INDEX((VideoTimeStamps!$A:$A=$B25)*ISNUMBER(SEARCH(I$2, VideoTimeStamps!$E:$E)), 0), 0)), ""))} | J25: {=IF(OR($B25="", J$2=""), "", IFERROR(INDEX(VideoTimeStamps!$C:$C, MATCH(1, INDEX((VideoTimeStamps!$A:$A=$B25)*ISNUMBER(SEARCH(J$2, VideoTimeStamps!$E:$E)), 0), 0)), ""))} | K25: {=IF(OR($B25="", K$2=""), "", IFERROR(INDEX(VideoTimeStamps!$C:$C, MATCH(1, INDEX((VideoTimeStamps!$A:$A=$B25)*ISNUMBER(SEARCH(K$2, VideoTimeStamps!$E:$E)), 0), 0)), ""))} | ... Q25: {=IF(OR($B25="", Q$2=""), "", IFERROR(INDEX(VideoTimeStamps!$C:$C, MATCH(1, INDEX((VideoTimeStamps!$A:$A=$B25)*ISNUMBER(SEARCH(Q$2, VideoTimeStamps!$E:$E)), 0), 0)), ""))}
A26: FALSE | D26: {=IF(OR($B26="", D$2=""), "", IFERROR(INDEX(VideoTimeStamps!$C:$C, MATCH(1, INDEX((VideoTimeStamps!$A:$A=$B26)*ISNUMBER(SEARCH(D$2, VideoTimeStamps!$E:$E)), 0), 0)), ""))} | E26: {=IF(OR($B26="", E$2=""), "", IFERROR(INDEX(VideoTimeStamps!$C:$C, MATCH(1, INDEX((VideoTimeStamps!$A:$A=$B26)*ISNUMBER(SEARCH(E$2, VideoTimeStamps!$E:$E)), 0), 0)), ""))} | F26: {=IF(OR($B26="", F$2=""), "", IFERROR(INDEX(VideoTimeStamps!$C:$C, MATCH(1, INDEX((VideoTimeStamps!$A:$A=$B26)*ISNUMBER(SEARCH(F$2, VideoTimeStamps!$E:$E)), 0), 0)), ""))} | G26: {=IF(OR($B26="", G$2=""), "", IFERROR(INDEX(VideoTimeStamps!$C:$C, MATCH(1, INDEX((VideoTimeStamps!$A:$A=$B26)*ISNUMBER(SEARCH(G$2, VideoTimeStamps!$E:$E)), 0), 0)), ""))} | H26: {=IF(OR($B26="", H$2=""), "", IFERROR(INDEX(VideoTimeStamps!$C:$C, MATCH(1, INDEX((VideoTimeStamps!$A:$A=$B26)*ISNUMBER(SEARCH(H$2, VideoTimeStamps!$E:$E)), 0), 0)), ""))} | I26: {=IF(OR($B26="", I$2=""), "", IFERROR(INDEX(VideoTimeStamps!$C:$C, MATCH(1, INDEX((VideoTimeStamps!$A:$A=$B26)*ISNUMBER(SEARCH(I$2, VideoTimeStamps!$E:$E)), 0), 0)), ""))} | J26: {=IF(OR($B26="", J$2=""), "", IFERROR(INDEX(VideoTimeStamps!$C:$C, MATCH(1, INDEX((VideoTimeStamps!$A:$A=$B26)*ISNUMBER(SEARCH(J$2, VideoTimeStamps!$E:$E)), 0), 0)), ""))} | K26: {=IF(OR($B26="", K$2=""), "", IFERROR(INDEX(VideoTimeStamps!$C:$C, MATCH(1, INDEX((VideoTimeStamps!$A:$A=$B26)*ISNUMBER(SEARCH(K$2, VideoTimeStamps!$E:$E)), 0), 0)), ""))} | ... Q26: {=IF(OR($B26="", Q$2=""), "", IFERROR(INDEX(VideoTimeStamps!$C:$C, MATCH(1, INDEX((VideoTimeStamps!$A:$A=$B26)*ISNUMBER(SEARCH(Q$2, VideoTimeStamps!$E:$E)), 0), 0)), ""))}
A27: FALSE | D27: {=IF(OR($B27="", D$2=""), "", IFERROR(INDEX(VideoTimeStamps!$C:$C, MATCH(1, INDEX((VideoTimeStamps!$A:$A=$B27)*ISNUMBER(SEARCH(D$2, VideoTimeStamps!$E:$E)), 0), 0)), ""))} | E27: {=IF(OR($B27="", E$2=""), "", IFERROR(INDEX(VideoTimeStamps!$C:$C, MATCH(1, INDEX((VideoTimeStamps!$A:$A=$B27)*ISNUMBER(SEARCH(E$2, VideoTimeStamps!$E:$E)), 0), 0)), ""))} | F27: {=IF(OR($B27="", F$2=""), "", IFERROR(INDEX(VideoTimeStamps!$C:$C, MATCH(1, INDEX((VideoTimeStamps!$A:$A=$B27)*ISNUMBER(SEARCH(F$2, VideoTimeStamps!$E:$E)), 0), 0)), ""))} | G27: {=IF(OR($B27="", G$2=""), "", IFERROR(INDEX(VideoTimeStamps!$C:$C, MATCH(1, INDEX((VideoTimeStamps!$A:$A=$B27)*ISNUMBER(SEARCH(G$2, VideoTimeStamps!$E:$E)), 0), 0)), ""))} | H27: {=IF(OR($B27="", H$2=""), "", IFERROR(INDEX(VideoTimeStamps!$C:$C, MATCH(1, INDEX((VideoTimeStamps!$A:$A=$B27)*ISNUMBER(SEARCH(H$2, VideoTimeStamps!$E:$E)), 0), 0)), ""))} | I27: {=IF(OR($B27="", I$2=""), "", IFERROR(INDEX(VideoTimeStamps!$C:$C, MATCH(1, INDEX((VideoTimeStamps!$A:$A=$B27)*ISNUMBER(SEARCH(I$2, VideoTimeStamps!$E:$E)), 0), 0)), ""))} | J27: {=IF(OR($B27="", J$2=""), "", IFERROR(INDEX(VideoTimeStamps!$C:$C, MATCH(1, INDEX((VideoTimeStamps!$A:$A=$B27)*ISNUMBER(SEARCH(J$2, VideoTimeStamps!$E:$E)), 0), 0)), ""))} | K27: {=IF(OR($B27="", K$2=""), "", IFERROR(INDEX(VideoTimeStamps!$C:$C, MATCH(1, INDEX((VideoTimeStamps!$A:$A=$B27)*ISNUMBER(SEARCH(K$2, VideoTimeStamps!$E:$E)), 0), 0)), ""))} | ... Q27: {=IF(OR($B27="", Q$2=""), "", IFERROR(INDEX(VideoTimeStamps!$C:$C, MATCH(1, INDEX((VideoTimeStamps!$A:$A=$B27)*ISNUMBER(SEARCH(Q$2, VideoTimeStamps!$E:$E)), 0), 0)), ""))}
A28: FALSE | D28: {=IF(OR($B28="", D$2=""), "", IFERROR(INDEX(VideoTimeStamps!$C:$C, MATCH(1, INDEX((VideoTimeStamps!$A:$A=$B28)*ISNUMBER(SEARCH(D$2, VideoTimeStamps!$E:$E)), 0), 0)), ""))} | E28: {=IF(OR($B28="", E$2=""), "", IFERROR(INDEX(VideoTimeStamps!$C:$C, MATCH(1, INDEX((VideoTimeStamps!$A:$A=$B28)*ISNUMBER(SEARCH(E$2, VideoTimeStamps!$E:$E)), 0), 0)), ""))} | F28: {=IF(OR($B28="", F$2=""), "", IFERROR(INDEX(VideoTimeStamps!$C:$C, MATCH(1, INDEX((VideoTimeStamps!$A:$A=$B28)*ISNUMBER(SEARCH(F$2, VideoTimeStamps!$E:$E)), 0), 0)), ""))} | G28: {=IF(OR($B28="", G$2=""), "", IFERROR(INDEX(VideoTimeStamps!$C:$C, MATCH(1, INDEX((VideoTimeStamps!$A:$A=$B28)*ISNUMBER(SEARCH(G$2, VideoTimeStamps!$E:$E)), 0), 0)), ""))} | H28: {=IF(OR($B28="", H$2=""), "", IFERROR(INDEX(VideoTimeStamps!$C:$C, MATCH(1, INDEX((VideoTimeStamps!$A:$A=$B28)*ISNUMBER(SEARCH(H$2, VideoTimeStamps!$E:$E)), 0), 0)), ""))} | I28: {=IF(OR($B28="", I$2=""), "", IFERROR(INDEX(VideoTimeStamps!$C:$C, MATCH(1, INDEX((VideoTimeStamps!$A:$A=$B28)*ISNUMBER(SEARCH(I$2, VideoTimeStamps!$E:$E)), 0), 0)), ""))} | J28: {=IF(OR($B28="", J$2=""), "", IFERROR(INDEX(VideoTimeStamps!$C:$C, MATCH(1, INDEX((VideoTimeStamps!$A:$A=$B28)*ISNUMBER(SEARCH(J$2, VideoTimeStamps!$E:$E)), 0), 0)), ""))} | K28: {=IF(OR($B28="", K$2=""), "", IFERROR(INDEX(VideoTimeStamps!$C:$C, MATCH(1, INDEX((VideoTimeStamps!$A:$A=$B28)*ISNUMBER(SEARCH(K$2, VideoTimeStamps!$E:$E)), 0), 0)), ""))} | ... Q28: {=IF(OR($B28="", Q$2=""), "", IFERROR(INDEX(VideoTimeStamps!$C:$C, MATCH(1, INDEX((VideoTimeStamps!$A:$A=$B28)*ISNUMBER(SEARCH(Q$2, VideoTimeStamps!$E:$E)), 0), 0)), ""))}
A29: FALSE | D29: {=IF(OR($B29="", D$2=""), "", IFERROR(INDEX(VideoTimeStamps!$C:$C, MATCH(1, INDEX((VideoTimeStamps!$A:$A=$B29)*ISNUMBER(SEARCH(D$2, VideoTimeStamps!$E:$E)), 0), 0)), ""))} | E29: {=IF(OR($B29="", E$2=""), "", IFERROR(INDEX(VideoTimeStamps!$C:$C, MATCH(1, INDEX((VideoTimeStamps!$A:$A=$B29)*ISNUMBER(SEARCH(E$2, VideoTimeStamps!$E:$E)), 0), 0)), ""))} | F29: {=IF(OR($B29="", F$2=""), "", IFERROR(INDEX(VideoTimeStamps!$C:$C, MATCH(1, INDEX((VideoTimeStamps!$A:$A=$B29)*ISNUMBER(SEARCH(F$2, VideoTimeStamps!$E:$E)), 0), 0)), ""))} | G29: {=IF(OR($B29="", G$2=""), "", IFERROR(INDEX(VideoTimeStamps!$C:$C, MATCH(1, INDEX((VideoTimeStamps!$A:$A=$B29)*ISNUMBER(SEARCH(G$2, VideoTimeStamps!$E:$E)), 0), 0)), ""))} | H29: {=IF(OR($B29="", H$2=""), "", IFERROR(INDEX(VideoTimeStamps!$C:$C, MATCH(1, INDEX((VideoTimeStamps!$A:$A=$B29)*ISNUMBER(SEARCH(H$2, VideoTimeStamps!$E:$E)), 0), 0)), ""))} | I29: {=IF(OR($B29="", I$2=""), "", IFERROR(INDEX(VideoTimeStamps!$C:$C, MATCH(1, INDEX((VideoTimeStamps!$A:$A=$B29)*ISNUMBER(SEARCH(I$2, VideoTimeStamps!$E:$E)), 0), 0)), ""))} | J29: {=IF(OR($B29="", J$2=""), "", IFERROR(INDEX(VideoTimeStamps!$C:$C, MATCH(1, INDEX((VideoTimeStamps!$A:$A=$B29)*ISNUMBER(SEARCH(J$2, VideoTimeStamps!$E:$E)), 0), 0)), ""))} | K29: {=IF(OR($B29="", K$2=""), "", IFERROR(INDEX(VideoTimeStamps!$C:$C, MATCH(1, INDEX((VideoTimeStamps!$A:$A=$B29)*ISNUMBER(SEARCH(K$2, VideoTimeStamps!$E:$E)), 0), 0)), ""))} | ... Q29: {=IF(OR($B29="", Q$2=""), "", IFERROR(INDEX(VideoTimeStamps!$C:$C, MATCH(1, INDEX((VideoTimeStamps!$A:$A=$B29)*ISNUMBER(SEARCH(Q$2, VideoTimeStamps!$E:$E)), 0), 0)), ""))}
A30: FALSE | D30: {=IF(OR($B30="", D$2=""), "", IFERROR(INDEX(VideoTimeStamps!$C:$C, MATCH(1, INDEX((VideoTimeStamps!$A:$A=$B30)*ISNUMBER(SEARCH(D$2, VideoTimeStamps!$E:$E)), 0), 0)), ""))} | E30: {=IF(OR($B30="", E$2=""), "", IFERROR(INDEX(VideoTimeStamps!$C:$C, MATCH(1, INDEX((VideoTimeStamps!$A:$A=$B30)*ISNUMBER(SEARCH(E$2, VideoTimeStamps!$E:$E)), 0), 0)), ""))} | F30: {=IF(OR($B30="", F$2=""), "", IFERROR(INDEX(VideoTimeStamps!$C:$C, MATCH(1, INDEX((VideoTimeStamps!$A:$A=$B30)*ISNUMBER(SEARCH(F$2, VideoTimeStamps!$E:$E)), 0), 0)), ""))} | G30: {=IF(OR($B30="", G$2=""), "", IFERROR(INDEX(VideoTimeStamps!$C:$C, MATCH(1, INDEX((VideoTimeStamps!$A:$A=$B30)*ISNUMBER(SEARCH(G$2, VideoTimeStamps!$E:$E)), 0), 0)), ""))} | H30: {=IF(OR($B30="", H$2=""), "", IFERROR(INDEX(VideoTimeStamps!$C:$C, MATCH(1, INDEX((VideoTimeStamps!$A:$A=$B30)*ISNUMBER(SEARCH(H$2, VideoTimeStamps!$E:$E)), 0), 0)), ""))} | I30: {=IF(OR($B30="", I$2=""), "", IFERROR(INDEX(VideoTimeStamps!$C:$C, MATCH(1, INDEX((VideoTimeStamps!$A:$A=$B30)*ISNUMBER(SEARCH(I$2, VideoTimeStamps!$E:$E)), 0), 0)), ""))} | J30: {=IF(OR($B30="", J$2=""), "", IFERROR(INDEX(VideoTimeStamps!$C:$C, MATCH(1, INDEX((VideoTimeStamps!$A:$A=$B30)*ISNUMBER(SEARCH(J$2, VideoTimeStamps!$E:$E)), 0), 0)), ""))} | K30: {=IF(OR($B30="", K$2=""), "", IFERROR(INDEX(VideoTimeStamps!$C:$C, MATCH(1, INDEX((VideoTimeStamps!$A:$A=$B30)*ISNUMBER(SEARCH(K$2, VideoTimeStamps!$E:$E)), 0), 0)), ""))} | ... Q30: {=IF(OR($B30="", Q$2=""), "", IFERROR(INDEX(VideoTimeStamps!$C:$C, MATCH(1, INDEX((VideoTimeStamps!$A:$A=$B30)*ISNUMBER(SEARCH(Q$2, VideoTimeStamps!$E:$E)), 0), 0)), ""))}
A31: FALSE | D31: {=IF(OR($B31="", D$2=""), "", IFERROR(INDEX(VideoTimeStamps!$C:$C, MATCH(1, INDEX((VideoTimeStamps!$A:$A=$B31)*ISNUMBER(SEARCH(D$2, VideoTimeStamps!$E:$E)), 0), 0)), ""))} | E31: {=IF(OR($B31="", E$2=""), "", IFERROR(INDEX(VideoTimeStamps!$C:$C, MATCH(1, INDEX((VideoTimeStamps!$A:$A=$B31)*ISNUMBER(SEARCH(E$2, VideoTimeStamps!$E:$E)), 0), 0)), ""))} | F31: {=IF(OR($B31="", F$2=""), "", IFERROR(INDEX(VideoTimeStamps!$C:$C, MATCH(1, INDEX((VideoTimeStamps!$A:$A=$B31)*ISNUMBER(SEARCH(F$2, VideoTimeStamps!$E:$E)), 0), 0)), ""))} | G31: {=IF(OR($B31="", G$2=""), "", IFERROR(INDEX(VideoTimeStamps!$C:$C, MATCH(1, INDEX((VideoTimeStamps!$A:$A=$B31)*ISNUMBER(SEARCH(G$2, VideoTimeStamps!$E:$E)), 0), 0)), ""))} | H31: {=IF(OR($B31="", H$2=""), "", IFERROR(INDEX(VideoTimeStamps!$C:$C, MATCH(1, INDEX((VideoTimeStamps!$A:$A=$B31)*ISNUMBER(SEARCH(H$2, VideoTimeStamps!$E:$E)), 0), 0)), ""))} | I31: {=IF(OR($B31="", I$2=""), "", IFERROR(INDEX(VideoTimeStamps!$C:$C, MATCH(1, INDEX((VideoTimeStamps!$A:$A=$B31)*ISNUMBER(SEARCH(I$2, VideoTimeStamps!$E:$E)), 0), 0)), ""))} | J31: {=IF(OR($B31="", J$2=""), "", IFERROR(INDEX(VideoTimeStamps!$C:$C, MATCH(1, INDEX((VideoTimeStamps!$A:$A=$B31)*ISNUMBER(SEARCH(J$2, VideoTimeStamps!$E:$E)), 0), 0)), ""))} | K31: {=IF(OR($B31="", K$2=""), "", IFERROR(INDEX(VideoTimeStamps!$C:$C, MATCH(1, INDEX((VideoTimeStamps!$A:$A=$B31)*ISNUMBER(SEARCH(K$2, VideoTimeStamps!$E:$E)), 0), 0)), ""))} | ... Q31: {=IF(OR($B31="", Q$2=""), "", IFERROR(INDEX(VideoTimeStamps!$C:$C, MATCH(1, INDEX((VideoTimeStamps!$A:$A=$B31)*ISNUMBER(SEARCH(Q$2, VideoTimeStamps!$E:$E)), 0), 0)), ""))}
A32: FALSE | D32: {=IF(OR($B32="", D$2=""), "", IFERROR(INDEX(VideoTimeStamps!$C:$C, MATCH(1, INDEX((VideoTimeStamps!$A:$A=$B32)*ISNUMBER(SEARCH(D$2, VideoTimeStamps!$E:$E)), 0), 0)), ""))} | E32: {=IF(OR($B32="", E$2=""), "", IFERROR(INDEX(VideoTimeStamps!$C:$C, MATCH(1, INDEX((VideoTimeStamps!$A:$A=$B32)*ISNUMBER(SEARCH(E$2, VideoTimeStamps!$E:$E)), 0), 0)), ""))} | F32: {=IF(OR($B32="", F$2=""), "", IFERROR(INDEX(VideoTimeStamps!$C:$C, MATCH(1, INDEX((VideoTimeStamps!$A:$A=$B32)*ISNUMBER(SEARCH(F$2, VideoTimeStamps!$E:$E)), 0), 0)), ""))} | G32: {=IF(OR($B32="", G$2=""), "", IFERROR(INDEX(VideoTimeStamps!$C:$C, MATCH(1, INDEX((VideoTimeStamps!$A:$A=$B32)*ISNUMBER(SEARCH(G$2, VideoTimeStamps!$E:$E)), 0), 0)), ""))} | H32: {=IF(OR($B32="", H$2=""), "", IFERROR(INDEX(VideoTimeStamps!$C:$C, MATCH(1, INDEX((VideoTimeStamps!$A:$A=$B32)*ISNUMBER(SEARCH(H$2, VideoTimeStamps!$E:$E)), 0), 0)), ""))} | I32: {=IF(OR($B32="", I$2=""), "", IFERROR(INDEX(VideoTimeStamps!$C:$C, MATCH(1, INDEX((VideoTimeStamps!$A:$A=$B32)*ISNUMBER(SEARCH(I$2, VideoTimeStamps!$E:$E)), 0), 0)), ""))} | J32: {=IF(OR($B32="", J$2=""), "", IFERROR(INDEX(VideoTimeStamps!$C:$C, MATCH(1, INDEX((VideoTimeStamps!$A:$A=$B32)*ISNUMBER(SEARCH(J$2, VideoTimeStamps!$E:$E)), 0), 0)), ""))} | K32: {=IF(OR($B32="", K$2=""), "", IFERROR(INDEX(VideoTimeStamps!$C:$C, MATCH(1, INDEX((VideoTimeStamps!$A:$A=$B32)*ISNUMBER(SEARCH(K$2, VideoTimeStamps!$E:$E)), 0), 0)), ""))} | ... Q32: {=IF(OR($B32="", Q$2=""), "", IFERROR(INDEX(VideoTimeStamps!$C:$C, MATCH(1, INDEX((VideoTimeStamps!$A:$A=$B32)*ISNUMBER(SEARCH(Q$2, VideoTimeStamps!$E:$E)), 0), 0)), ""))}
A33: FALSE | D33: {=IF(OR($B33="", D$2=""), "", IFERROR(INDEX(VideoTimeStamps!$C:$C, MATCH(1, INDEX((VideoTimeStamps!$A:$A=$B33)*ISNUMBER(SEARCH(D$2, VideoTimeStamps!$E:$E)), 0), 0)), ""))} | E33: {=IF(OR($B33="", E$2=""), "", IFERROR(INDEX(VideoTimeStamps!$C:$C, MATCH(1, INDEX((VideoTimeStamps!$A:$A=$B33)*ISNUMBER(SEARCH(E$2, VideoTimeStamps!$E:$E)), 0), 0)), ""))} | F33: {=IF(OR($B33="", F$2=""), "", IFERROR(INDEX(VideoTimeStamps!$C:$C, MATCH(1, INDEX((VideoTimeStamps!$A:$A=$B33)*ISNUMBER(SEARCH(F$2, VideoTimeStamps!$E:$E)), 0), 0)), ""))} | G33: {=IF(OR($B33="", G$2=""), "", IFERROR(INDEX(VideoTimeStamps!$C:$C, MATCH(1, INDEX((VideoTimeStamps!$A:$A=$B33)*ISNUMBER(SEARCH(G$2, VideoTimeStamps!$E:$E)), 0), 0)), ""))} | H33: {=IF(OR($B33="", H$2=""), "", IFERROR(INDEX(VideoTimeStamps!$C:$C, MATCH(1, INDEX((VideoTimeStamps!$A:$A=$B33)*ISNUMBER(SEARCH(H$2, VideoTimeStamps!$E:$E)), 0), 0)), ""))} | I33: {=IF(OR($B33="", I$2=""), "", IFERROR(INDEX(VideoTimeStamps!$C:$C, MATCH(1, INDEX((VideoTimeStamps!$A:$A=$B33)*ISNUMBER(SEARCH(I$2, VideoTimeStamps!$E:$E)), 0), 0)), ""))} | J33: {=IF(OR($B33="", J$2=""), "", IFERROR(INDEX(VideoTimeStamps!$C:$C, MATCH(1, INDEX((VideoTimeStamps!$A:$A=$B33)*ISNUMBER(SEARCH(J$2, VideoTimeStamps!$E:$E)), 0), 0)), ""))} | K33: {=IF(OR($B33="", K$2=""), "", IFERROR(INDEX(VideoTimeStamps!$C:$C, MATCH(1, INDEX((VideoTimeStamps!$A:$A=$B33)*ISNUMBER(SEARCH(K$2, VideoTimeStamps!$E:$E)), 0), 0)), ""))} | ... Q33: {=IF(OR($B33="", Q$2=""), "", IFERROR(INDEX(VideoTimeStamps!$C:$C, MATCH(1, INDEX((VideoTimeStamps!$A:$A=$B33)*ISNUMBER(SEARCH(Q$2, VideoTimeStamps!$E:$E)), 0), 0)), ""))}
... A42: FALSE | D42: {=IF(OR($B42="", D$2=""), "", IFERROR(INDEX(VideoTimeStamps!$C:$C, MATCH(1, INDEX((VideoTimeStamps!$A:$A=$B42)*ISNUMBER(SEARCH(D$2, VideoTimeStamps!$E:$E)), 0), 0)), ""))} | E42: {=IF(OR($B42="", E$2=""), "", IFERROR(INDEX(VideoTimeStamps!$C:$C, MATCH(1, INDEX((VideoTimeStamps!$A:$A=$B42)*ISNUMBER(SEARCH(E$2, VideoTimeStamps!$E:$E)), 0), 0)), ""))} | F42: {=IF(OR($B42="", F$2=""), "", IFERROR(INDEX(VideoTimeStamps!$C:$C, MATCH(1, INDEX((VideoTimeStamps!$A:$A=$B42)*ISNUMBER(SEARCH(F$2, VideoTimeStamps!$E:$E)), 0), 0)), ""))} | G42: {=IF(OR($B42="", G$2=""), "", IFERROR(INDEX(VideoTimeStamps!$C:$C, MATCH(1, INDEX((VideoTimeStamps!$A:$A=$B42)*ISNUMBER(SEARCH(G$2, VideoTimeStamps!$E:$E)), 0), 0)), ""))} | H42: {=IF(OR($B42="", H$2=""), "", IFERROR(INDEX(VideoTimeStamps!$C:$C, MATCH(1, INDEX((VideoTimeStamps!$A:$A=$B42)*ISNUMBER(SEARCH(H$2, VideoTimeStamps!$E:$E)), 0), 0)), ""))} | I42: {=IF(OR($B42="", I$2=""), "", IFERROR(INDEX(VideoTimeStamps!$C:$C, MATCH(1, INDEX((VideoTimeStamps!$A:$A=$B42)*ISNUMBER(SEARCH(I$2, VideoTimeStamps!$E:$E)), 0), 0)), ""))} | J42: {=IF(OR($B42="", J$2=""), "", IFERROR(INDEX(VideoTimeStamps!$C:$C, MATCH(1, INDEX((VideoTimeStamps!$A:$A=$B42)*ISNUMBER(SEARCH(J$2, VideoTimeStamps!$E:$E)), 0), 0)), ""))} | K42: {=IF(OR($B42="", K$2=""), "", IFERROR(INDEX(VideoTimeStamps!$C:$C, MATCH(1, INDEX((VideoTimeStamps!$A:$A=$B42)*ISNUMBER(SEARCH(K$2, VideoTimeStamps!$E:$E)), 0), 0)), ""))} | ... Q42: {=IF(OR($B42="", Q$2=""), "", IFERROR(INDEX(VideoTimeStamps!$C:$C, MATCH(1, INDEX((VideoTimeStamps!$A:$A=$B42)*ISNUMBER(SEARCH(Q$2, VideoTimeStamps!$E:$E)), 0), 0)), ""))}
A43: FALSE
A44: FALSE
A45: FALSE
A46: FALSE
A47: FALSE
A48: FALSE
A49: FALSE
...

Sheet VideoTimeStamps
A1: Group Name | B1: Clip Name | C1: Clip Link | D1: Characters | E1: Actions
A2: Jorynn | B2: Jorynn_Child_Assessment.mov | C2: https://drive.google.com/file/d/1gP5r4ZmK0CC65l_jcaxt93cPx3SVZq0l/view?usp=drivesdk | D2: girl | E2: girl points at book (00:00 - 00:08), girl places card in book (00:08 - 00:10), girl flips pages in book (00:10 - 00:20), girl rests head on hand (00:20 - 00:30), girl smiles (00:24 - 00:25), girl rubs eye (00:27 - 00:28)
A3: Jorynn | B3: Jorynn_Child_PassPaper.mov | C3: https://drive.google.com/file/d/1NKe8zfUqXz_KdZYyYh4eJGbo5bs6z3nv/view?usp=drivesdk | D3: girl | E3: girl looking at paper (00:00 - 00:04), girl looking at paper (00:07 - 00:09), girl smiling (00:01 - 00:02), girl holding paper (00:04 - 00:07), girl flipping paper (00:09 - 00:11)
A4: Jorynn | B4: Jorynn_ParentChild_Holding_KooBits.mov | C4: https://drive.google.com/file/d/1n2dqAdTCQK-0MF8KE7SaUgvxH9ruzNMS/view?usp=drivesdk | D4: woman and girl | E4: woman pointing at girl's arm (00:00 - 00:01), woman pointing at tablet (00:01 - 00:06), woman giving a thumbs up (00:06 - 00:10), girl clenching her fist (00:06 - 00:10)
A5: Jorynn | B5: Jorynn_Child_Video.mov | C5: https://drive.google.com/file/d/1m9qVYqa6TlznYKmurcR1PWbx3qTi2-nA/view?usp=drivesdk | D5: child | E5: child is using a tablet (00:00 - 00:41), child is looking at the camera (00:41 - 00:47)
A6: Jorynn | B6: Jorynn_Parent_Assessment.mov | C6: https://drive.google.com/file/d/1ntSNpubcTcLHfPH89yqa_Qd0lcCnEEW4/view?usp=drivesdk | D6: woman | E6: woman reading book (00:00 - 00:05), woman flipping pages (00:05 - 00:08), woman smiling and pointing (00:08 - 00:13)
A7: Jorynn | B7: Jorynn_ParentChild_Assessment_PassingKooBits.mov | C7: https://drive.google.com/file/d/1up7eHkP8TUTOPQP1PbvQap4cNOxYvlTX/view?usp=drivesdk | D7: woman and girl, girl | E7: woman and girl are looking at a book (00:00 - 00:05), girl rests her head on her hand (00:05 - 00:09), woman points at the book and girl looks at it (00:09 - 00:15), girl points at the book (00:15 - 00:20), woman points at the book while girl looks (00:20 - 00:27), woman closes the book and girl leans back (00:27 - 00:30), woman places and opens a tablet for girl (00:30 - 00:39)
A8: Jorynn | B8: Jorynn_Parent_Relaxing.mov | C8: https://drive.google.com/file/d/1-Xd4yfIi6RzjZw8ieSTHNmIsvVxuHzhF/view?usp=drivesdk | D8: woman | E8: woman looks at phone (00:00 - 00:05), woman picks up drink (00:05 - 00:06), woman sips drink (00:06 - 00:11), woman smiles (00:11 - 00:12), woman puts down drink (00:12 - 00:13)
A9: Jorynn | B9: Jorynn_Child_FailPaper.mov | C9: https://drive.google.com/file/d/1Oy_TCnOKirQZ2Nw56qwMUsPfJRTA58dr/view?usp=drivesdk | D9: girl | E9: girl looking at paper (00:00 - 00:03), girl resting her head on her hand (00:03 - 00:05), girl resting her head on her hand (00:10 - 00:12), girl resting her head on her hand (00:15 - 00:19), girl talking (00:05 - 00:08), girl looking down at paper (00:08 - 00:10), girl looking down at paper (00:12 - 00:15)
A10: Jorynn | B10: Jorynn_Child_Question.mov | C10: https://drive.google.com/file/d/1KYLvAQLhXiBKfut_8km_MOJOuVFPGdRw/view?usp=drivesdk | D10: woman and girl | E10: woman and girl looking at tablet (00:00 - 00:05), woman and girl looking at tablet (00:11 - 00:12), girl tapping on tablet (00:05 - 00:08), woman and girl clapping hands (00:08 - 00:11)
A11: Jorynn | B11: Jorynn_Child_Question 2.mov | C11: https://drive.google.com/file/d/1YkDuIXIcM5acoo29fIjHeTftN5TahjXy/view?usp=drivesdk | D11: girl | E11: girl looking at tablet (00:00 - 00:04), girl tilting tablet (00:01 - 00:02), girl touching tablet screen (00:04 - 00:19), girl raising fists and smiling (00:19 - 00:22), girl smiling and looking at tablet (00:22 - 00:25)
A12: Jorynn | B12: Jorynn_Child_Playing.mov | C12: https://drive.google.com/file/d/1YuFVKDJQjrwPiOGqzwh0Eon4MSX20bL9/view?usp=drivesdk | D12: girl | E12: girl holding object (00:00 - 00:02), girl holding object (00:04 - 00:06), girl holding object (00:08 - 00:10), girl looking at object (00:02 - 00:04), girl holding pen and object (00:06 - 00:08), girl holding pen and object (00:14 - 00:19), girl holding pen (00:10 - 00:12), girl playing with fingers (00:12 - 00:14)
... A312: Chan | B312: Chan_Dec2026_Parentrelax.mov | C312: https://drive.google.com/file/d/1NONNONdiv3FbHbUmdKhL1hHLWkMFdiTF/view?usp=drivesdk | D312: woman | E312: woman drinking from a mug (00:00 - 00:04), woman smiling (00:04 - 00:09)

Sheet Master KW
A1: girl points at book
A2: girl places card in book
A3: girl flips pages in book
A4: girl rests head on hand
A5: girl smiles
A6: girl rubs eye
A7: girl looking at paper
A8: girl smiling
A9: girl holding paper
A10: girl flipping paper
A11: woman pointing at girl's arm
A12: woman pointing at tablet
... A1270: woman smiling
